Workbook

Sheet Cross-Decade Comparison
A1: 135 Eastern Parkway (Turner Towers) — Domestic Servants Across Census Decades
A2: Sourced from the '1930 Summary', '1940 Summary', and '1950 Summary' tabs.
A4: Metric | B4: 1930 | C4: 1940 | D4: 1950 | E4: Trend Notes
A5: Total identified servants/household workers | B5: ='1930 Summary'!B3 -> 64 | C5: ='1940 Summary'!B3 -> 89 | D5: ='1950 Summary'!B3 -> 35 | E5: 1940 count is inflated relative to 1930/1950 because this ED's extracted pages covered the whole building far more comprehensively (174+ units) than the 1930/1950 excerpts; treat the 1940 raw total as an upper bound, not a like-for-like figure.
A6: Black servants/household workers | B6: ='1930 Summary'!B7 -> 3 | C6: ='1940 Summary'!B11 -> 23 | D6: ='1950 Summary'!B7 -> 9
A7: White servants/household workers | B7: ='1930 Summary'!B6 -> 61 | C7: ='1940 Summary'!B10 -> 66 | D7: ='1950 Summary'!B6 -> 26
A8: Black as % of total | B8: =IFERROR(B6/B5,0) -> 0.046875 | C8: =IFERROR(C6/C5,0) -> 0.25842697 | D8: =IFERROR(D6/D5,0) -> 0.25714286 | E8: Black share jumps sharply from 1930 (4.7%) to 1940 (25.8%), then holds essentially flat into 1950 (25.7%) — most of the shift happened by 1940, not gradually.
A9: Foreign-born servants | B9: ='1930 Summary'!B16 -> 58 | C9: ='1940 Summary'!B21 -> 37 | D9: ='1950 Summary'!B18 -> 22
A10: U.S.-born servants | B10: ='1930 Summary'!B15 -> 6 | C10: ='1940 Summary'!B20 -> 52 | D10: ='1950 Summary'!B17 -> 13
A11: Foreign-born as % of total | B11: =IFERROR(B9/B5,0) -> 0.90625 | C11: =IFERROR(C9/C5,0) -> 0.41573034 | D11: =IFERROR(D9/D5,0) -> 0.62857143 | E11: NOT monotonic: foreign-born share falls sharply from ~90.6% (1930) to ~41.6% (1940), then partly rebounds to ~65.7% (1950). The 1940 dip may reflect this sample's fuller building coverage picking up more U.S.-born (including Black Southern-born) workers rather than a real one-decade reversal and rebound; worth checking against a normalized (per-apartment) count if that matters for your analysis.
A12: Average age | B12: ='1930 Summary'!B27 -> 27.71875 | C12: ='1940 Summary'!B31 -> 31.640449 | D12: ='1950 Summary'!B30 -> 45.142857 | E12: Servants got markedly older on average across the three decades — consistent with an aging, shrinking pool of career domestics rather than a steady inflow of young workers.
A13: Median age | B13: ='1930 Summary'!B28 -> 24 | C13: ='1940 Summary'!B32 -> 29 | D13: ='1950 Summary'!B31 -> 45
A14: Most common occupation title | B14: Servant/Maid | C14: Housekeeper | D14: Maid | E14: Title terminology shifts by decade/enumerator rather than necessarily reflecting a change in job content; 'Housekeeper' becomes the dominant 1940 term for what 1930/1950 mostly call 'Servant/Maid' or 'Maid'.
A16: Notes:
A17: - 1930 figures exclude one flagged duplicate entry (Sigrid Christensen, servant to the Rosenfeld household) - see the '1930 Servants' tab. Two additional 1930 records (Harding, Dora and Schilling, Resi) are included from Sheet 274, whose visit numbers fall within the 135 Eastern Parkway range despite the sheet being headed 'Apt 159'.
A18: - 1940 figures include a supplemental sheet (61A) that consolidates several 'continued' housekeeper entries from earlier 1940 sheets; a handful of these could not be confidently matched back to a specific household and are flagged accordingly on the '1940 Servants' tab.
A19: - 1950 figures reflect only sheets/lines with clearly identifiable domestic servants; a small number of ambiguous relationship codes are flagged on the '1950 Servants' tab.
A20: - IMPORTANT CAVEAT ON RAW TOTALS: the 1940 enumeration extracted here appears to cover substantially more of the building (up to ~174 units) than the 1930 and 1950 excerpts did, so the raw 'Total identified servants' row is not a reliable measure of the trend in domestic-staffing levels by itself. The percentage-based rows (Black %, Foreign-born %) and the age statistics are more robust to this coverage difference, since they are normalized within each decade's own sample.
A21: - Because 1930, 1940, and 1950 differ in how enumerators coded relationship vs. occupation (e.g., some 1950 domestic workers are listed as heads of their own household line; several 1930 governesses/institutional nurses and 1940 'private practice'/'hospital' nurses are borderline cases), treat cross-decade comparisons as directional rather than precise.
A22: - "Race" reflects each census's contemporary enumerator classification (White/Negro) as recorded on the original schedules.

Sheet Top Households
A1: 135 Eastern Parkway (Turner Towers) — Households with the Most Servants
A2: Combined across the 1930, 1940, and 1950 census rosters. Households are ranked by total identified servants within a single decade (households are not combined across decades, since staff and even head-of-household names may differ over 10-20 years).
A3: AI-generated. Beware of often inaccurate transcriptions, especially of name spellings.
A4: Rank | B4: Household (Head) | C4: Decade | D4: Servant Count | E4: Servants (Name — Occupation) | F4: Notes
A5: 1 | B5: Starr, Herman | C5: 1930 | D5: 3 | E5: Wallace, Louise (Cook); Veda(?), Frances (Waitress); Werner, Jane (Nurse)
A6: 1 | B6: Nova, Barnett | C6: 1940 | D6: 3 | E6: Cooley, Eleanor (Nurse); Copper, Glenn (Butler); Copper, Freda (Cook)
A7: 3 | B7: Jones, Milton | C7: 1930 | D7: 2 | E7: Breman, Helen (Nurse); Gehrken, Christel (Servant/Maid)
A8: 3 | B8: Rust, Alfred H. | C8: 1930 | D8: 2 | E8: Fiser(?), Carla (Nurse); Kelleher, Emma (Cook)
A9: 3 | B9: Burdick, Clinton D. | C9: 1930 | D9: 2 | E9: Ohlson, Ulricka(?) (Cook); Storrsken(?), Selma (Servant/Maid)
A10: 3 | B10: Davis, Jacob | C10: 1930 | D10: 2 | E10: Ottenwalder(?), Elinor(?) (Nurse); Rader, Theresa (Servant/Maid)
A11: 3 | B11: Paswell, Benjamin(?) | C11: 1930 | D11: 2 | E11: Tertig(?), Marie (Servant/Maid); Sable, Rose (Nurse) | F11: Sable, Rose listed as 'Nurse, Doctor's Office' - may be a professional lodger rather than domestic staff
A12: 3 | B12: Leskis(?), Erving T. | C12: 1930 | D12: 2 | E12: Campbell, Susan (Nurse); Albrecht, Emma (Cook) | F12: Employer surname uncertain
A13: 3 | B13: Baar, Jesse | C13: 1930 | D13: 2 | E13: Grolz, Olga (Servant/Maid); Isries(?), Marie (Servant/Maid)
A14: 3 | B14: Burdick, Howard | C14: 1930 | D14: 2 | E14: McAllister, Margaret (Nurse); Lynch, Margaret (Cook)
A15: 3 | B15: Gustig(?), Jerome B. | C15: 1930 | D15: 2 | E15: Klingau(?), Josephine (Maid); Plosh(?), Katie (Cook) | F15: Names uncertain
A16: 3 | B16: Briskman, Samuel | C16: 1940 | D16: 2 | E16: Conlin, Helen (Housekeeper); Martis, Julia (Housekeeper)
A17: 3 | B17: Weintraub, Maurice | C17: 1940 | D17: 2 | E17: Laparia, Elizabeth (Housekeeper); Canadle, Elizabeth (Nurse) | F17: Canadle, Elizabeth appears on the 61A supplemental sheet as a continuation of this household
A18: 3 | B18: Parnes, Samuel R. | C18: 1940 | D18: 2 | E18: Piscal, Adele (Cook); Erickson, Laura (Nurse)
A19: 3 | B19: Gumpert, Lilie | C19: 1940 | D19: 2 | E19: Bryan, Anne (Housekeeper); Goldstein, Miriam (Nurse) | F19: Household assignment for Goldstein, Miriam is ambiguous on the source sheet
A20: 3 | B20: Zinn, Martain | C20: 1940 | D20: 2 | E20: Dopkowsky, Annetti (Housekeeper); Kwiatkowski(?), Sopie (Housekeeper) | F20: Kwiatkowski(?) appears on the 61A supplemental sheet as a continuation of this household
A21: 3 | B21: Hirsh, Henry | C21: 1940 | D21: 2 | E21: Luchow, Jennie (Nurse); Smith, Irene (Housekeeper)
A22: 3 | B22: Dolsky, Archie | C22: 1940 | D22: 2 | E22: Rammirez, Gus (Chauffeur); Rammirez, Anner (Cook) | F22: Apparent married couple both employed by the same household
A24: Notes:
A25: - Two households tie for first place with 3 servants each: Starr, Herman (1930) and Nova, Barnett (1940). No single decade or household has more than 3 identified servants in this dataset.
A26: - Beyond the top 2, sixteen households tie at 2 servants each, so there is no clean, non-arbitrary 'top 10' cutoff - all 16 are listed here rather than truncating the tie.
A27: - Rankings are calculated within each decade separately; the same building or even the same family across decades may show up more than once if the head-of-household name persisted (none did in this dataset - no repeat households appear across 1930/1940/1950 at this servant-count threshold).
A28: - The flagged 1930 duplicate entry (Sigrid Christensen, Rosenfeld household) was excluded before ranking, so Rosenfeld, Daniel does not appear here despite showing 2 raw rows in the source data.
A29: - No 1950 household reaches 2 servants among the top-ranked list shown here; the highest 1950 households (Parnes, Edward and Novro, Barnett J., both with 2 servants) are tied with the group above but are omitted purely for space - see the '1950 Servants' tab for the full roster.
A30: - 1930 households dominate this list (9 of 11 non-tied-for-first entries), consistent with 1930 showing the highest servant-to-household intensity of the three decades - see the 'Cross-Decade Comparison' tab.

Sheet 1930 Servants
A1: 135 Eastern Parkway (Turner Towers), Brooklyn — 1930 U.S. Census
A2: Domestic servant / household worker roster — ED 24-1491, Apt. 135, Sheets 259-277 (13A-32A) plus visits 614-615 on Sheet 274 (28A), Enumerator Tillie Swenson (Apr 9-21, 1930)
A3: AI-generated. Beware of often inaccurate transcriptions, especially of name spellings.
A4: Sheet | B4: Line | C4: Servant Name | D4: Occupation | E4: Age | F4: Sex | G4: Marital Status | H4: Birthplace | I4: Race | J4: Employing Head of Household | K4: House No. | L4: Notes
A5: 259/13A | B5: 5 | C5: Korn, Josephine | D5: Maid | E5: 19 | F5: F | G5: S | H5: New York | I5: White | J5: Turner, Samuel S. | K5: 256
A6: 259/13A | B6: 10 | C6: Wuchter, Adrina | D6: Servant/Maid | E6: 20 | F6: F | G6: S | H6: Germany | I6: White | J6: Moss, Abraham | K6: 258
A7: 259/13A | B7: 14 | C7: Karlsen, Ella | D7: Servant/Maid | E7: 26 | F7: F | G7: S | H7: Norway | I7: White | J7: Mayer, Edwin | K7: 259
A8: 259/13A | B8: 21 | C8: Trowers, Bridget | D8: Servant/Maid | E8: 22 | F8: F | G8: S | H8: Ireland | I8: White | J8: Holzer, Morton | K8: 260
A9: 259/13A | B9: 30 | C9: Eickemeyer, Marie | D9: Servant/Maid | E9: 22 | F9: F | G9: S | H9: Germany | I9: White | J9: Saltzer, Annie | K9: 263
A10: 259/13A | B10: 37 | C10: Breman, Helen | D10: Nurse | E10: 30 | F10: F | G10: S | H10: Ireland | I10: White | J10: Jones, Milton | K10: 265
A11: 259/13A | B11: 38 | C11: Gehrken, Christel | D11: Servant/Maid | E11: 20 | F11: F | G11: S | H11: Germany | I11: White | J11: Jones, Milton | K11: 265
A12: 259/13B | B12: 51 | C12: Devine, Nora | D12: Servant/Maid | E12: 18 | F12: F | G12: S | H12: Irish Free State | I12: White | J12: Pensig, Samuel (cont.) | K12: 269
A13: 259/13B | B13: 60 | C13: Emma (surname illegible) | D13: Servant/Maid | E13: 20 | F13: F | G13: S | H13: Germany | I13: White | J13: Ivry, Clarence | K13: 272 | L13: First name only legible
A14: 259/13B | B14: 70 | C14: Nunn(?), Teresa | D14: Servant/Maid | E14: 20 | F14: F | G14: S | H14: Scotland | I14: White | J14: Kaplan, Morris | K14: 275 | L14: Surname uncertain
A15: 259/13B | B15: 80 | C15: Hoier, Anna | D15: Servant/Maid | E15: 35 | F15: F | G15: S | H15: Germany | I15: White | J15: Balzor(?), David | K15: 279 | L15: Employer surname uncertain
A16: 259/13B | B16: 85 | C16: Whelan, Delia M. | D16: Servant/Maid | E16: 39 | F16: F | G16: S | H16: Ireland (Dublin) | I16: White | J16: Witte, Paul | K16: 280
A17: 259/13B | B17: 91 | C17: Embree, Alice F. | D17: Nurse | E17: 44 | F17: F | G17: S | H17: New York | I17: White | J17: Platt, Harriet R. | K17: 282
A18: 260/14A | B18: 3 | C18: Mazur, Frances | D18: Servant/Maid | E18: 20 | F18: F | G18: S | H18: Poland | I18: White | J18: Pearlman, Harry (cont.) | K18: 285
A19: 260/14A | B19: 19 | C19: Neary, Jane T.(?) | D19: Servant/Maid | E19: 23 | F19: F | G19: S | H19: West Ireland | I19: White | J19: Cohn, Max | K19: 290 | L19: First name possibly misread
A20: 260/14A | B20: 23 | C20: Fiser(?), Carla | D20: Nurse | E20: 24 | F20: F | G20: S | H20: Germany | I20: White | J20: Rust, Alfred H. | K20: 309 | L20: Surname uncertain
A21: 260/14A | B21: 24 | C21: Kelleher, Emma | D21: Cook | E21: 46 | F21: F | G21: S | H21: Germany | I21: White | J21: Rust, Alfred H. | K21: 309
A22: 260/14A | B22: 30 | C22: Schmidt, Ford L.(?) | D22: Nurse | E22: 27 | F22: F | G22: S | H22: Norway | I22: White | J22: Gourrich, Paul E. | K22: 311 | L22: First name uncertain
A23: 260/14A | B23: 37 | C23: Rinehold, Anna | D23: Servant/Maid | E23: 21 | F23: F | G23: S | H23: Germany | I23: White | J23: Parnes, Samuel R. | K23: 314
A24: 260/14A | B24: 45 | C24: Wieland, Emilie | D24: Servant/Maid | E24: 19 | F24: F | G24: S | H24: Germany | I24: White | J24: Marcus, Alex | K24: 316
A25: 260/14A | B25: 48 | C25: Prusch, Paula | D25: Servant/Maid | E25: 24 | F25: F | G25: S | H25: Germany | I25: White | J25: Kellner, William | K25: 317
A26: 260/14B | B26: 57 | C26: Bezner, Elizabeth | D26: Servant/Maid | E26: 38 | F26: F | G26: S | H26: Austria | I26: White | J26: Markes, Henry M. | K26: 322
A27: 260/14B | B27: 62 | C27: McCormack, Margaret B. | D27: Servant/Maid | E27: 26 | F27: F | G27: S | H27: Ireland | I27: White | J27: Shapiro, Simon | K27: 323
A28: 260/14B | B28: 78 | C28: Ohlson, Ulricka(?) | D28: Cook | E28: 50 | F28: F | G28: S | H28: Sweden | I28: White | J28: Burdick, Clinton D. | K28: 331 | L28: First name uncertain
A29: 260/14B | B29: 79 | C29: Storrsken(?), Selma | D29: Servant/Maid | E29: 29 | F29: F | G29: S | H29: Norway | I29: White | J29: Burdick, Clinton D. | K29: 331 | L29: Surname uncertain
A30: 260/14B | B30: 86 | C30: Vernoy, Stella | D30: Servant/Maid | E30: 22 | F30: F | G30: S | H30: Poland | I30: White | J30: Weinstock, Louis | K30: 332
A31: 260/14B | B31: 94 | C31: Neary, Catherine | D31: Servant/Maid | E31: 26 | F31: F | G31: S | H31: Ireland | I31: White | J31: Schener, Samuel | K31: 334
A32: 263/17A | B32: 1 | C32: Palari, Edla | D32: Servant/Maid | E32: 55 | F32: F | G32: S | H32: Finland | I32: White | J32: Emery, Grover C. (cont.) | K32: 336
A33: 263/17A | B33: 6 | C33: Ottenwalder(?), Elinor(?) | D33: Nurse | E33: 29 | F33: F | G33: S | H33: Germany | I33: White | J33: Davis, Jacob | K33: 337 | L33: Name uncertain
A34: 263/17A | B34: 7 | C34: Rader, Theresa | D34: Servant/Maid | E34: 48 | F34: F | G34: S | H34: Germany | I34: White | J34: Davis, Jacob | K34: 337
A35: 263/17A | B35: 18 | C35: Tennant, Peter(?) | D35: Governess | E35: 39 | F35: F | G35: Wd | H35: Sydney, Australia | I35: White | J35: Wurman, Harry P. | K35: 339 | L35: First name likely misread (female)
A36: 263/17A | B36: 28 | C36: Helander, Elda | D36: Domestic | E36: 42 | F36: F | G36: S | H36: Finland | I36: White | J36: Schwartz, Julius | K36: 341
A37: 263/17A | B37: 36 | C37: Sheck, Anna | D37: Cook | E37: 30 | F37: F | G37: S | H37: Germany | I37: White | J37: Ashman, Maurice(?) | K37: 343 | L37: Employer surname uncertain
A38: 263/17A | B38: 41 | C38: May, Eva | D38: Servant/Maid | E38: 25 | F38: F | G38: S | H38: Germany | I38: White | J38: Prosky, Samuel | K38: 344
A39: 263/17A | B39: 45 | C39: Eklund, Astrid | D39: Servant/Maid | E39: 21 | F39: F | G39: S | H39: Norway | I39: White | J39: Johnson, David C. | K39: 345
A40: 263/17A | B40: 50 | C40: Alnes(?), Antonia | D40: Servant/Maid | E40: 20 | F40: F | G40: S | H40: Germany | I40: White | J40: Romberg, William | K40: 346 | L40: Surname uncertain
...

Sheet 1930 Summary
A1: 135 Eastern Parkway — 1930 Servant Summary Statistics
A3: Total identified servants/household workers | B3: =COUNTA('1930 Servants'!$C$5:$C$68) -> 64
A5: By Race
A6: White | B6: =COUNTIF('1930 Servants'!$I$5:$I$68,"White") -> 61
A7: Black | B7: =COUNTIF('1930 Servants'!$I$5:$I$68,"Black") -> 3
A9: By Marital Status
A10: Single (Nev. Mar.) | B10: =COUNTIF('1930 Servants'!$G$5:$G$68,"S") -> 62
A11: Widowed | B11: =COUNTIF('1930 Servants'!$G$5:$G$68,"Wd") -> 1
A12: Married | B12: =COUNTIF('1930 Servants'!$G$5:$G$68,"Mar") -> 1
A14: U.S.-born vs. Foreign-born
A15: U.S.-born (sum of U.S. state birthplaces) | B15: =COUNTIF('1930 Servants'!$H$5:$H$68,"New York")+COUNTIF('1930 Servants'!$H$5:$H$68,"North Carolina") -> 6
A16: Foreign-born (Total − U.S.-born) | B16: =B3-B15 -> 58
A18: Occupation Title Breakdown
A19: Servant/Maid | B19: =COUNTIF('1930 Servants'!$D$5:$D$68,"Servant/Maid") -> 39
A20: Maid | B20: =COUNTIF('1930 Servants'!$D$5:$D$68,"Maid") -> 3
A21: Cook | B21: =COUNTIF('1930 Servants'!$D$5:$D$68,"Cook") -> 10
A22: Nurse | B22: =COUNTIF('1930 Servants'!$D$5:$D$68,"Nurse") -> 9
A23: Domestic | B23: =COUNTIF('1930 Servants'!$D$5:$D$68,"Domestic") -> 1
A24: Governess | B24: =COUNTIF('1930 Servants'!$D$5:$D$68,"Governess") -> 1
A25: Waitress | B25: =COUNTIF('1930 Servants'!$D$5:$D$68,"Waitress") -> 1
A27: Average Age | B27: =AVERAGE('1930 Servants'!$E$5:$E$68) -> 27.71875
A28: Median Age | B28: =MEDIAN('1930 Servants'!$E$5:$E$68) -> 24
A30: Note: One additional entry (Sigrid Christensen, likely duplicate) is excluded from these totals - see notes on the '1930 Servants' tab.

Sheet 1940 Servants
A1: 135 Eastern Parkway (Turner Towers), Brooklyn — 1940 U.S. Census
A2: Domestic servant / household worker roster — S.D. 5, E.D. 24-1200, Sheets 1A-8B plus supplemental Sheet 61A, Enumerator Thomas Higgins (Apr 2-8, 1940)
A3: AI-generated. Beware of often inaccurate transcriptions, especially of name spellings.
A4: Sheet | B4: Line | C4: Servant Name | D4: Occupation | E4: Age | F4: Sex | G4: Marital Status | H4: Birthplace | I4: Race | J4: Employing Head of Household | K4: Apt/Unit No. | L4: Notes
A5: 1A | B5: 6 | C5: Cooley, Eleanor | D5: Nurse | E5: 47 | F5: F | G5: S | H5: New York | I5: White | J5: Nova, Barnett | K5: 1
A6: 1A | B6: 7 | C6: Copper, Glenn | D6: Butler | E6: 25 | F6: M | G6: Mar | H6: Iowa | I6: Black | J6: Nova, Barnett | K6: 1
A7: 1A | B7: 8 | C7: Copper, Freda | D7: Cook | E7: 25 | F7: F | G7: Mar | H7: Florida | I7: Black | J7: Nova, Barnett | K7: 1
A8: 1A | B8: 20 | C8: Pekar, Cornelia | D8: Housekeeper | E8: 25 | F8: F | G8: S | H8: Pennsylvania | I8: White | J8: Zeitz, Harry | K8: 6
A9: 1A | B9: 26 | C9: Conlin, Helen | D9: Housekeeper | E9: 30 | F9: F | G9: S | H9: Ireland (Eire) | I9: White | J9: Briskman, Samuel | K9: 9
A10: 1A | B10: 31 | C10: Martis, Julia | D10: Housekeeper | E10: 60 | F10: F | G10: S | H10: Ireland (Eire) | I10: White | J10: Briskman, Samuel | K10: 9 | L10: Sex column possibly misread as M; treated as female given first name
A11: 1A | B11: 36 | C11: Nilbert, Emma | D11: Housekeeper | E11: 42 | F11: F | G11: S | H11: Germany | I11: White | J11: Lukon, Herman | K11: 11
A12: 1B | B12: 46 | C12: Dewispf(?), Palma | D12: Housekeeper | E12: 44 | F12: F | G12: S | H12: Pennsylvania | I12: White | J12: Karesh, Solomon | K12: 15 | L12: Surname uncertain
A13: 1B | B13: 51 | C13: Rakowitz, Stella | D13: Housekeeper | E13: 23 | F13: F | G13: S | H13: Austria | I13: White | J13: Freuden, Harry | K13: 16
A14: 1B | B14: 56 | C14: Stroska, Catherine | D14: Housekeeper | E14: 28 | F14: F | G14: S | H14: Pennsylvania | I14: White | J14: Obstfeld, Lou | K14: 17
A15: 1B | B15: 63 | C15: McFadden, Margaret | D15: Housekeeper | E15: 30 | F15: F | G15: S | H15: Ireland | I15: White | J15: Shapiro, Simon | K15: 19
A16: 1B | B16: 72 | C16: McCabe, Mary | D16: Housekeeper | E16: 44 | F16: F | G16: S | H16: Connecticut (Greenwich) | I16: White | J16: Weit, Gordon | K16: 23
A17: 2A | B17: 1 | C17: Laparia, Elizabeth | D17: Housekeeper | E17: 26 | F17: F | G17: S | H17: Pennsylvania | I17: White | J17: Weintraub, Maurice | K17: 25
A18: 2A | B18: 9 | C18: Wolf, Clara | D18: Housekeeper | E18: 23 | F18: F | G18: S | H18: Germany | I18: White | J18: Edelman, Alex | K18: 28
A19: 2A | B19: 12 | C19: Marchstain, Margaret | D19: Housekeeper | E19: 39 | F19: F | G19: S | H19: Romania | I19: White | J19: Tuch, Michael | K19: 29
A20: 2A | B20: 29 | C20: Piscal, Adele | D20: Cook | E20: 27 | F20: F | G20: S | H20: Germany | I20: White | J20: Parnes, Samuel R. | K20: 35
A21: 2A | B21: 30 | C21: Erickson, Laura | D21: Nurse | E21: 23 | F21: F | G21: S | H21: Michigan (Detroit) | I21: White | J21: Parnes, Samuel R. | K21: 35
A22: 2B | B22: 43 | C22: Burke, Margaret | D22: Housekeeper | E22: 43 | F22: F | G22: S | H22: Northern Ireland | I22: White | J22: Steinman, Ben | K22: 39
A23: 2B | B23: 51 | C23: Robinson, Virginia | D23: Housekeeper | E23: 28 | F23: F | G23: S | H23: Florida | I23: Black | J23: Hirsch, Harry | K23: 41
A24: 2B | B24: 56 | C24: Regner, Elizabeth | D24: Housekeeper | E24: 48 | F24: F | G24: S | H24: Germany | I24: White | J24: Marks, Harry | K24: 42
... A26: 2B | B26: 73 | C26: Maciolek, Isabell | D26: Housekeeper | E26: 18 | F26: F | G26: S | H26: Pennsylvania | I26: White | J26: Rosenberg, Gerald | K26: 47
A27: 3A | B27: 5 | C27: Mitchil, Betty | D27: Housework | E27: 28 | F27: F | G27: S | H27: Massachusetts | I27: White | J27: Salgman(?), Moe | K27: 52 | L27: Employer surname uncertain
A28: 3A | B28: 23 | C28: Escuiry(?), Marise | D28: Housekeeper | E28: 69 | F28: F | G28: Wd | H28: Hungary | I28: White | J28: Kurtz, Joseph | K28: 56 | L28: Name uncertain
A29: 3A | B29: 31 | C29: Stringfield, Margaret | D29: Housekeeper | E29: 26 | F29: F | G29: S | H29: North Carolina | I29: Black | J29: Jeskowitz, Herman | K29: 58
A30: 3A | B30: 37 | C30: Purcell, Clara | D30: Housekeeper | E30: 27 | F30: F | G30: S | H30: Virginia | I30: Black | J30: Meizels, Julius | K30: 60
A31: 3B | B31: 43 | C31: Rankl, Juatta | D31: Nurse | E31: 30 | F31: F | G31: S | H31: Germany | I31: White | J31: Goldstein, Nathaniel | K31: 62 | L31: Occupation listed as 'Nurse, Private Practice' rather than domestic service; included for completeness and flagged
A32: 3B | B32: 47 | C32: Pechulis, Anna | D32: Housekeeper | E32: 34 | F32: F | G32: S | H32: Pennsylvania | I32: White | J32: Goldburg, Maurice | K32: 63
A33: 3B | B33: 54 | C33: Eugster, Bertha | D33: Housekeeper | E33: 45 | F33: F | G33: S | H33: Switzerland | I33: White | J33: Shapiro, Louis | K33: 65
A34: 3B | B34: 59 | C34: Gubernack, Helen | D34: Housekeeper | E34: 24 | F34: F | G34: S | H34: Pennsylvania | I34: White | J34: Ellenoff, Frank | K34: 66
A35: 3B | B35: 63 | C35: Bozko, Leokadia | D35: Housekeeper | E35: 34 | F35: F | G35: S | H35: New York | I35: White | J35: Shapiro, Jacob | K35: 67
A36: 3B | B36: 77 | C36: Shaposka(?), Jaulene(?) | D36: Housekeeper | E36: 18 | F36: F | G36: S | H36: Pennsylvania | I36: White | J36: Ginzberg, Henry | K36: 71 | L36: Name uncertain
A37: 4A | B37: 6 | C37: Nilson, Pearl | D37: Housekeeper | E37: 27 | F37: F | G37: S | H37: Virginia | I37: Black | J37: Dick, Samuel | K37: 74
A38: 4A | B38: 15 | C38: Bryan, Anne | D38: Housekeeper | E38: 25 | F38: F | G38: S | H38: Pennsylvania | I38: White | J38: Gumpert, Lilie | K38: 78
A39: 4A | B39: 16 | C39: Goldstein, Miriam | D39: Nurse | E39: 23 | F39: F | G39: S | H39: New Jersey | I39: White | J39: Gumpert, Lilie | K39: 78 | L39: Household/unit assignment for lines 16-18 (Waldman) is ambiguous on this sheet
A40: 4A | B40: 28 | C40: Kitchner, Anne | D40: Housekeeper | E40: 19 | F40: F | G40: S | H40: Pennsylvania | I40: White | J40: Scharf, Harry | K40: 81
A41: 4B | B41: 41 | C41: Loughlan, Mary | D41: Housekeeper | E41: 32 | F41: F | G41: S | H41: Irish Free State | I41: White | J41: Kahn, Arsthur (cont.) | K41: 84
...

Sheet 1940 Summary
A1: 135 Eastern Parkway — 1940 Servant Summary Statistics
A3: Total identified servants/household workers | B3: =COUNTA('1940 Servants'!$C$5:$C$93) -> 89
A5: By Sex
A6: Female | B6: =COUNTIF('1940 Servants'!$F$5:$F$93,"F") -> 87
A7: Male | B7: =COUNTIF('1940 Servants'!$F$5:$F$93,"M") -> 2
A9: By Race
A10: White | B10: =COUNTIF('1940 Servants'!$I$5:$I$93,"White") -> 66
A11: Black | B11: =COUNTIF('1940 Servants'!$I$5:$I$93,"Black") -> 23
A13: By Marital Status
A14: Single | B14: =COUNTIF('1940 Servants'!$G$5:$G$93,"S") -> 73
A15: Widowed | B15: =COUNTIF('1940 Servants'!$G$5:$G$93,"Wd") -> 8
A16: Married | B16: =COUNTIF('1940 Servants'!$G$5:$G$93,"Mar") -> 6
A17: Divorced | B17: =COUNTIF('1940 Servants'!$G$5:$G$93,"Div") -> 2
A19: U.S.-born vs. Foreign-born
A20: U.S.-born (sum of U.S. state birthplaces) | B20: =COUNTIF('1940 Servants'!$H$5:$H$93,"New York")+COUNTIF('1940 Servants'!$H$5:$H$93,"New York (Bronx)")+COUNTIF('1940 Servants'!$H$5:$H$93,"Massachusetts")+COUNTIF('1940 Servants'!$H$5:$H$93,"Pennsylvania")+COUNTIF('1940 Servants'!$H$5:$H$93,"Pennsylvania (Johnstown)")+COUNTIF('1940 Servants'!$H$5:$H$93,"Pennsylvania (Hilldale)")+COUNTIF('1940 Servants'!$H$5:$H$93,"Connecticut (Greenwich)")+COUNTIF('1940 Servants'!$H$5:$H$93,"Michigan (Detroit)")+COUNTIF('1940 Servants'!$H$5:$H$93,"North Carolina")+COUNTIF('1940 Servants'!$H$5:$H$93,"Virginia")+COUNTIF('1940 Servants'!$H$5:$H$93,"Virginia (Whaleyville)")+COUNTIF('1940 Servants'!$H$5:$H$93,"Louisiana")+COUNTIF('1940 Servants'!$H$5:$H$93,"Louisiana (New Orleans)")+COUNTIF('1940 Servants'!$H$5:$H$93,"Ohio (Cincinnati)")+COUNTIF('1940 Servants'!$H$5:$H$93,"Ohio (Chicago)")+COUNTIF('1940 Servants'!$H$5:$H$93,"West Virginia (Morgantown)")+COUNTIF('1940 Servants'!$H$5:$H$93,"Delaware (Wilmington)")+COUNTIF('1940 Servants'!$H$5:$H$93,"Florida")+COUNTIF('1940 Servants'!$H$5:$H$93,"Georgia")+COUNTIF('1940 Servants'!$H$5:$H$93,"South Carolina (Florence)")+COUNTIF('1940 Servants'!$H$5:$H$93,"New Jersey")+COUNTIF('1940 Servants'!$H$5:$H$93,"Iowa (Chicago)")+COUNTIF('1940 Servants'!$H$5:$H$93,"New York (Lodi, NJ)") -> 52
A21: Foreign-born (Total − U.S.-born) | B21: =B3-B20 -> 37
A23: Occupation Title Breakdown
A24: Housekeeper | B24: =COUNTIF('1940 Servants'!$D$5:$D$93,"Housekeeper") -> 74
A25: Cook | B25: =COUNTIF('1940 Servants'!$D$5:$D$93,"Cook") -> 4
A26: Nurse | B26: =COUNTIF('1940 Servants'!$D$5:$D$93,"Nurse") -> 8
A27: Butler | B27: =COUNTIF('1940 Servants'!$D$5:$D$93,"Butler") -> 1
A28: Chauffeur | B28: =COUNTIF('1940 Servants'!$D$5:$D$93,"Chauffeur") -> 1
A29: Housework | B29: =COUNTIF('1940 Servants'!$D$5:$D$93,"Housework") -> 1
A31: Average Age | B31: =AVERAGE('1940 Servants'!$E$5:$E$93) -> 31.640449
A32: Median Age | B32: =MEDIAN('1940 Servants'!$E$5:$E$93) -> 29
A34: Note: 1940 uses 'Housekeeper' as the dominant occupation title on this schedule, roughly equivalent to 'Maid'/'Servant' in the 1930 and 1950 schedules.

Sheet 1950 Servants
A1: 135 Eastern Parkway (Turner Towers), Brooklyn — 1950 U.S. Census
A2: Domestic servant / household worker roster — ED 24-1447, Sheets 17-36, Enumerator Charles E. White (Apr 13 - May 1, 1950)
A3: AI-generated. Beware of often inaccurate transcriptions, especially of name spellings.
A4: Sheet | B4: Line | C4: Servant Name | D4: Occupation | E4: Age | F4: Sex | G4: Marital Status | H4: Birthplace | I4: Race | J4: Employing Head of Household | K4: Hours/Week | L4: Notes
A5: 18 | B5: 5 | C5: Dombtschewska, Irene | D5: Housework | E5: 55 | F5: F | G5: Wd | H5: Ukraine | I5: White | J5: Cohen, Meyer | K5: 45
A6: 19 | B6: 14 | C6: Teravanin, Hilda | D6: General Maid | E6: 41 | F6: F | G6: Nev | H6: Massachusetts | I6: White | J6: Salwen, Nathan | K6: 48
A7: 19 | B7: 29 | C7: (Kasenaty?), Anna | D7: Maid (mother-in-law of head) | E7: 64 | F7: F | G7: Wd | H7: Russia(?) | I7: White | J7: Brown / household at line 29 | L7: Handwriting ambiguous; relationship listed as mother-in-law
A8: 19 | B8: 30 | C8: Brown, Mae | D8: Domestic | E8: 21 | F8: F | G8: D | H8: Virginia | I8: Black | J8: Hirsch, Reuben | K8: 48
A9: 21 | B9: 7 | C9: Walsh, Mary | D9: Baby Nurse | E9: 63 | F9: F | G9: Nev | H9: Ireland | I9: White | J9: Yaffe, Maurice | K9: 60
A10: 21 | B10: 15 | C10: Fee, Philomena | D10: Maid | E10: 19 | F10: F | G10: Nev | H10: Ireland | I10: White | J10: Pensig, Herbert | K10: 49
A11: 21 | B11: 28 | C11: Whitman, Dora | D11: Maid | E11: 63 | F11: F | G11: Wd | H11: South Carolina | I11: Black | J11: Dorff, George | K11: 48
A12: 23 | B12: 13 | C12: Clinksales(?), Mary | D12: Maid | E12: 38 | F12: F | G12: Wd | H12: South Carolina | I12: Black | J12: Bildersee, Adele | K12: 48
A13: 23 | B13: 21 | C13: Viot, Marguerite | D13: Maid | E13: 61 | F13: F | G13: Nev | H13: Alsace-Lorraine | I13: White | J13: Tuch, Michael | K13: 48
A14: 23 | B14: 26 | C14: Mulhern, Annie | D14: Maid | E14: 30 | F14: F | G14: Nev | H14: Ireland | I14: White | J14: Brenner, Phillip | K14: 48
A15: 23 | B15: 29 | C15: Thompson, Mabel | D15: Maid | E15: 40 | F15: F | G15: Sep | H15: North Carolina | I15: Black | J15: (own household, line 29) | K15: 48 | L15: Listed as head of own line; live-in servant status inferred
A16: 24 | B16: 4 | C16: Pisklak(?), Adele | D16: Maid | E16: 36 | F16: F | G16: Nev | H16: Czechoslovakia | I16: White | J16: Parnes, Samuel R. | K16: 48
A17: 24 | B17: 6 | C17: Regner, Elizabeth | D17: Housekeeper / Domestic | E17: 58 | F17: F | G17: Nev | H17: Austria | I17: White | J17: Marks, Harry M. | K17: 48
A18: 24 | B18: 9 | C18: Moodie, Sarah | D18: Maid | E18: 58 | F18: F | G18: Wd | H18: England | I18: White | J18: Needle, Harry | K18: 48
A19: 24 | B19: 12 | C19: Gielenska, Anna | D19: Maid | E19: 31 | F19: F | G19: Nev | H19: Poland | I19: White | J19: Niman, Rose | K19: 48
A20: 24 | B20: 23 | C20: Tchinkel(?), Olga | D20: Maid | E20: 22 | F20: F | G20: Nev | H20: Czechoslovakia | I20: White | J20: Parnes, Edward | K20: 48
A21: 24 | B21: 24 | C21: Kelly, Mary | D21: Maid | E21: 28 | F21: F | G21: Nev | H21: Ireland | I21: White | J21: Parnes, Edward | K21: 48
A22: 26 | B22: 19 | C22: Auerbach, Tony | D22: Nursemaid (Child) | E22: 49 | F22: F | G22: Nev | H22: Germany | I22: White | J22: Aron, Helen | K22: 48
A23: 27 | B23: 6 | C23: Philbert, Hazeline | D23: Maid | E23: 38 | F23: F | G23: Sep | H23: Georgia | I23: Black | J23: Wasserman, Arnold C. | K23: 48
A24: 28 | B24: 18 | C24: Foster, Lummie | D24: Maid | E24: 54 | F24: F | G24: Nev | H24: Virginia | I24: Black | J24: Wasch, Milton G. | K24: 40
A25: 29 | B25: 13 | C25: Kersche(?), Angela | D25: Maid | E25: 45 | F25: F | G25: Nev | H25: Minnesota | I25: White | J25: Blume, Vivian | K25: 48
A26: 30 | B26: 29 | C26: Argousack(?), Rose | D26: Domestic | E26: 38 | F26: F | G26: Nev | H26: Pennsylvania | I26: White | J26: Strausburg, Morris | K26: 40
A27: 31 | B27: 6 | C27: Meyer, Johanna Marie | D27: Housekeeper | E27: 48 | F27: F | G27: Nev | H27: Germany | I27: White | J27: Fried, Aaron L. | K27: 40
... A39: 36 | B39: 3 | C39: Zieninski, Mary | D39: Domestic | E39: 49 | F39: F | G39: Nev | H39: Poland | I39: White | J39: Freedman, Etta / Jerome N. | K39: 60
A41: Notes:
A42: - Names/readings marked with (?) reflect uncertain handwriting on the original schedule; verify against the source image if needed.
A43: - Sheets 17, 20, 22, and 25 contained no identifiable live-in servants and are excluded from this roster.
A44: - Line 19/29 (Anna, listed as mother-in-law) and line 23/29 (Mabel Thompson, listed as household head) are included as likely domestic workers based on occupation/industry columns; relationship-to-head coding is ambiguous or atypical.
A45: - "Race" reflects the census enumerator's contemporary classification (White/Negro) as recorded on the schedule.
A47: Notes:
A48: - Names/readings marked with (?) reflect uncertain handwriting on the original schedule; verify against the source image if needed.
A49: - Sheets 17, 20, 22, and 25 contained no identifiable live-in servants and are excluded from this roster.
A50: - Line 19/29 (Anna, listed as mother-in-law) and line 23/29 (Mabel Thompson, listed as household head) are included as likely domestic workers based on occupation/industry columns; relationship-to-head coding is ambiguous or atypical.
A51: - "Race" reflects the census enumerator's contemporary classification (White/Negro) as recorded on the schedule.

Sheet 1950 Summary
A1: 135 Eastern Parkway — 1950 Servant Summary Statistics
A3: Total identified servants/household workers | B3: =COUNTA('1950 Servants'!$C$5:$C$39) -> 35
A5: By Race
A6: White | B6: =COUNTIF('1950 Servants'!$I$5:$I$39,"White") -> 26
A7: Black | B7: =COUNTIF('1950 Servants'!$I$5:$I$39,"Black") -> 9
A9: By Marital Status
A10: Never Married | B10: =COUNTIF('1950 Servants'!$G$5:$G$39,"Nev") -> 22
A11: Widowed | B11: =COUNTIF('1950 Servants'!$G$5:$G$39,"Wd") -> 7
A12: Separated | B12: =COUNTIF('1950 Servants'!$G$5:$G$39,"Sep") -> 4
A13: Divorced | B13: =COUNTIF('1950 Servants'!$G$5:$G$39,"D") -> 1
A14: Married | B14: =COUNTIF('1950 Servants'!$G$5:$G$39,"Mar") -> 1
A16: U.S.-born vs. Foreign-born
A17: U.S.-born (sum of U.S. state birthplaces) | B17: =COUNTIF('1950 Servants'!$H$5:$H$39,"New York")+COUNTIF('1950 Servants'!$H$5:$H$39,"Massachusetts")+COUNTIF('1950 Servants'!$H$5:$H$39,"New Jersey")+COUNTIF('1950 Servants'!$H$5:$H$39,"Virginia")+COUNTIF('1950 Servants'!$H$5:$H$39,"South Carolina")+COUNTIF('1950 Servants'!$H$5:$H$39,"North Carolina")+COUNTIF('1950 Servants'!$H$5:$H$39,"Georgia")+COUNTIF('1950 Servants'!$H$5:$H$39,"Pennsylvania")+COUNTIF('1950 Servants'!$H$5:$H$39,"Minnesota")+COUNTIF('1950 Servants'!$H$5:$H$39,"Louisiana") -> 13
A18: Foreign-born (Total − U.S.-born) | B18: =B3-B17 -> 22
A20: Occupation Title Breakdown
A21: Maid | B21: =COUNTIF('1950 Servants'!$D$5:$D$39,"*Maid*") -> 20
A22: Domestic | B22: =COUNTIF('1950 Servants'!$D$5:$D$39,"*Domestic*") -> 10
A23: Cook | B23: =COUNTIF('1950 Servants'!$D$5:$D$39,"*Cook*") -> 2
A24: Housekeeper | B24: =COUNTIF('1950 Servants'!$D$5:$D$39,"*Housekeeper*") -> 2
A25: Housework | B25: =COUNTIF('1950 Servants'!$D$5:$D$39,"*Housework*") -> 1
A26: General Maid | B26: =COUNTIF('1950 Servants'!$D$5:$D$39,"*General Maid*") -> 1
A27: Baby Nurse | B27: =COUNTIF('1950 Servants'!$D$5:$D$39,"*Baby Nurse*") -> 1
A28: Nursemaid (Child) | B28: =COUNTIF('1950 Servants'!$D$5:$D$39,"*Nursemaid (Child)*") -> 1
A30: Average Age | B30: =AVERAGE('1950 Servants'!$E$5:$E$39) -> 45.142857
A31: Median Age | B31: =MEDIAN('1950 Servants'!$E$5:$E$39) -> 45
A33: Occupation breakdown categories are not mutually exclusive (e.g. some entries combine titles like 'Housekeeper / Domestic').
